<?xml version="1.0"?>
<robot xmlns:xacro="http://www.ros.org/wiki/xacro" name="stretch_mast">

    <!-- Mast link -->
    <link name="link_mast">
        <inertial>
            <origin
                xyz="0.00755818572975822 0.773971284176834 0.00647313086620024"
                rpy="0 0 0"/>
            <mass value="0.749143203376401"/>
            <inertia
                ixx="0.0709854511954588"
                ixy="-0.00433428742758457"
                ixz="-0.000186110788697573"
                iyy="0.000437922053342648"
                iyz="-0.00288788257713431"
                izz="0.071104808501661" />
        </inertial>
        <visual>
            <origin xyz="0 0 0" rpy="0 0 0" />
            <geometry>
                <mesh
                    filename="package://stretch_description/meshes/link_mast.STL" />
            </geometry>
            <material name="">
                <color
                    rgba="0.792156862745098 0.819607843137255 0.933333333333333 1" />
            </material>
        </visual>
        <collision>
            <origin
                xyz="0 0 0"
                rpy="0 0 0" />
            <geometry>
                <mesh
                    filename="package://stretch_description/meshes/link_mast.STL" />
            </geometry>
        </collision>
    </link>

    <!-- Mast Joint -->
    <joint name="joint_mast" type="fixed">
        <origin
            xyz="-0.07 0.134999999999998 0.0284000000000001"
            rpy="1.5707963267949 0 0.00925318926571245"/>
        <parent link="base_link" />
        <child link="link_mast" />
        <axis xyz="0 0 0"/>
    </joint>

    <gazebo reference="joint_mast">
        <preserveFixedJoint>true</preserveFixedJoint>
    </gazebo>

    <!-- Lift Link and Joint -->
    <link name="link_lift">
        <inertial>
            <origin
                xyz="-0.0547636346252869 0.0380939689802074 0.00933159404448308"
                rpy="0 0 0"/>
            <mass value="0.444820831236007"/>
            <inertia
                ixx="0.000567192946271367"
                ixy="-0.00024607534789508"
                ixz="-0.000128108442260574"
                iyy="0.00127108364478659"
                iyz="7.61916855070339E-06"
                izz="0.00137296635099006" />
        </inertial>
        <visual>
            <origin xyz="0 0 0" rpy="0 0 0" />
            <geometry>
                <mesh
                    filename="package://stretch_description/meshes/link_lift.STL" />
            </geometry>
            <material name="">
                <color
                    rgba="0.792156862745098 0.819607843137255 0.933333333333333 1" />
            </material>
        </visual>
        <collision>
            <origin
                xyz="0 0 0"
                rpy="0 0 0" />
            <geometry>
                <mesh
                    filename="package://stretch_description/meshes/link_lift.STL" />
            </geometry>
        </collision>
    </link>

    <joint name="joint_lift" type="prismatic">
        <origin
            xyz="-0.0369217062323472 0.165471199999996 -0.000341653286793524"
            rpy="-1.57079632679552 1.5615431375292 -6.2942004366467E-13"/>
        <parent link="link_mast" />
        <child link="link_lift" />
        <axis xyz="0 0 1"/>
        <limit effort="100" lower="0.0" upper="1.1" velocity="1.0"/>
    </joint>

    <!-- Transmission block for gazebo -->
    <transmission name="trans_lift" type="SimpleTransmission">
        <type>transmission_interface/SimpleTransmission</type>
        <actuator name="lift_motor">
            <mechanicalReduction>1</mechanicalReduction>
        </actuator>
        <joint name="joint_lift">
            <hardwareInterface>hardware_interface/PositionJointInterface</hardwareInterface>
        </joint>
    </transmission>
    

</robot>
