<?xml version="1.0"?>
<robot xmlns:xacro="http://www.ros.org/wiki/xacro" name="stretch_right_wheel">
    <!-- Right Wheel Link -->
    <link name="link_right_wheel">
        <inertial>
            <origin
                xyz="1.25554620866719E-07 3.54748938447003E-07 0.0239581106165018"
                rpy="0 0 0" />
            <mass value="${0.00356714564938475}" />
            <inertia ixx="0" ixy="0" ixz="0"
                     iyy="0" iyz="0"
                     izz="0" />
        </inertial>
        <visual>
            <origin xyz="0 0 0" rpy="0 0 0"/>
            <geometry>
                <mesh 
                    filename="package://stretch_description/meshes/link_right_wheel.STL" />
            </geometry>
            <material name="">
                <color
                    rgba="0.792156862745098 0.819607843137255 0.933333333333333 1" />
            </material>
        </visual>
        <collision>
            <origin xyz="0 0 0" rpy="0 0 0"/>
            <geometry>
                <mesh 
                    filename="package://stretch_description/meshes/link_right_wheel.STL" />
            </geometry>
        </collision>
    </link>

    <!-- Right Wheel Link -->
    <joint name="joint_right_wheel" type="continuous">
        <origin
            xyz="-0.00300000000000034 -0.15765 0.0508000000000004"
            rpy="-1.57079632679489 -1.11022302462516E-16 7.28583859910277E-17" />
        <parent link="base_link" />
        <child link="link_right_wheel" />
        <axis xyz="0 0 1" />
    </joint>

    <!-- transmission block for ROS control -->
    <transmission name="trans_right_wheel">
        <type>transmission_interface/SimpleTransmission</type>
        <actuator name="right_wheel_motor">
            <mechanicalReduction>1</mechanicalReduction>
        </actuator>
        <joint name="joint_right_wheel">
            <hardwareInterface>hardware_interface/VelocityJointInterface</hardwareInterface>
        </joint>
    </transmission>

</robot>